[2025-05-01T15:07:26.355+0000] {local_task_job_runner.py:120} INFO - ::group::Pre task execution logs
[2025-05-01T15:07:26.460+0000] {taskinstance.py:2076} INFO - Dependencies all met for dep_context=non-requeueable deps ti=<TaskInstance: mysql_to_gcs.extract_from_mysql scheduled__2025-04-30T00:00:00+00:00 [queued]>
[2025-05-01T15:07:26.481+0000] {taskinstance.py:2076} INFO - Dependencies all met for dep_context=requeueable deps ti=<TaskInstance: mysql_to_gcs.extract_from_mysql scheduled__2025-04-30T00:00:00+00:00 [queued]>
[2025-05-01T15:07:26.484+0000] {taskinstance.py:2306} INFO - Starting attempt 1 of 1
[2025-05-01T15:07:26.652+0000] {taskinstance.py:2330} INFO - Executing <Task(PythonOperator): extract_from_mysql> on 2025-04-30 00:00:00+00:00
[2025-05-01T15:07:26.662+0000] {warnings.py:112} WARNING - /home/***/.local/lib/python3.12/site-packages/***/task/task_runner/standard_task_runner.py:61: DeprecationWarning: This process (pid=95) is multi-threaded, use of fork() may lead to deadlocks in the child.
  pid = os.fork()

[2025-05-01T15:07:26.666+0000] {standard_task_runner.py:63} INFO - Started process 98 to run task
[2025-05-01T15:07:26.665+0000] {standard_task_runner.py:90} INFO - Running: ['***', 'tasks', 'run', 'mysql_to_gcs', 'extract_from_mysql', 'scheduled__2025-04-30T00:00:00+00:00', '--job-id', '4', '--raw', '--subdir', 'DAGS_FOLDER/mysql_to_gcs_dag.py', '--cfg-path', '/tmp/tmpj10etc4y']
[2025-05-01T15:07:26.667+0000] {standard_task_runner.py:91} INFO - Job 4: Subtask extract_from_mysql
[2025-05-01T15:07:26.837+0000] {task_command.py:426} INFO - Running <TaskInstance: mysql_to_gcs.extract_from_mysql scheduled__2025-04-30T00:00:00+00:00 [running]> on host 34c72fae0f8a
[2025-05-01T15:07:27.227+0000] {taskinstance.py:2648} INFO - Exporting env vars: AIRFLOW_CTX_DAG_OWNER='***' AIRFLOW_CTX_DAG_ID='mysql_to_gcs' AIRFLOW_CTX_TASK_ID='extract_from_mysql' AIRFLOW_CTX_EXECUTION_DATE='2025-04-30T00:00:00+00:00' AIRFLOW_CTX_TRY_NUMBER='1' AIRFLOW_CTX_DAG_RUN_ID='scheduled__2025-04-30T00:00:00+00:00'
[2025-05-01T15:07:27.229+0000] {taskinstance.py:430} INFO - ::endgroup::
[2025-05-01T15:07:27.255+0000] {base.py:84} INFO - Using connection ID 'mysql_default' for task execution.
[2025-05-01T15:07:27.381+0000] {taskinstance.py:441} INFO - ::group::Post task execution logs
[2025-05-01T15:07:27.382+0000] {taskinstance.py:2905} ERROR - Task failed with exception
Traceback (most recent call last):
  File "/home/airflow/.local/lib/python3.12/site-packages/airflow/models/taskinstance.py", line 465, in _execute_task
    result = _execute_callable(context=context, **execute_callable_kwargs)
             ^^^^^^^^^^^^^^^^^^^^^^^^^^^^^^^^^^^^^^^^^^^^^^^^^^^^^^^^^^^^^
  File "/home/airflow/.local/lib/python3.12/site-packages/airflow/models/taskinstance.py", line 432, in _execute_callable
    return execute_callable(context=context, **execute_callable_kwargs)
           ^^^^^^^^^^^^^^^^^^^^^^^^^^^^^^^^^^^^^^^^^^^^^^^^^^^^^^^^^^^^
  File "/home/airflow/.local/lib/python3.12/site-packages/airflow/models/baseoperator.py", line 401, in wrapper
    return func(self, *args, **kwargs)
           ^^^^^^^^^^^^^^^^^^^^^^^^^^^
  File "/home/airflow/.local/lib/python3.12/site-packages/airflow/operators/python.py", line 235, in execute
    return_value = self.execute_callable()
                   ^^^^^^^^^^^^^^^^^^^^^^^
  File "/home/airflow/.local/lib/python3.12/site-packages/airflow/operators/python.py", line 252, in execute_callable
    return self.python_callable(*self.op_args, **self.op_kwargs)
           ^^^^^^^^^^^^^^^^^^^^^^^^^^^^^^^^^^^^^^^^^^^^^^^^^^^^^
  File "/opt/airflow/dags/mysql_to_gcs_dag.py", line 12, in extract_data_from_mysql
    df = mysql_hook.get_pandas_df(sql)
         ^^^^^^^^^^^^^^^^^^^^^^^^^^^^^
  File "/home/airflow/.local/lib/python3.12/site-packages/airflow/providers/common/sql/hooks/sql.py", line 262, in get_pandas_df
    with closing(self.get_conn()) as conn:
                 ^^^^^^^^^^^^^^^
  File "/home/airflow/.local/lib/python3.12/site-packages/airflow/providers/mysql/hooks/mysql.py", line 196, in get_conn
    return MySQLdb.connect(**conn_config)
           ^^^^^^^^^^^^^^^^^^^^^^^^^^^^^^
  File "/home/airflow/.local/lib/python3.12/site-packages/MySQLdb/__init__.py", line 121, in Connect
    return Connection(*args, **kwargs)
           ^^^^^^^^^^^^^^^^^^^^^^^^^^^
  File "/home/airflow/.local/lib/python3.12/site-packages/MySQLdb/connections.py", line 195, in __init__
    super().__init__(*args, **kwargs2)
MySQLdb.OperationalError: (2002, "Can't connect to local server through socket '/run/mysqld/mysqld.sock' (2)")
[2025-05-01T15:07:27.413+0000] {taskinstance.py:1206} INFO - Marking task as FAILED. dag_id=mysql_to_gcs, task_id=extract_from_mysql, run_id=scheduled__2025-04-30T00:00:00+00:00, execution_date=20250430T000000, start_date=20250501T150726, end_date=20250501T150727
[2025-05-01T15:07:27.463+0000] {standard_task_runner.py:110} ERROR - Failed to execute job 4 for task extract_from_mysql ((2002, "Can't connect to local server through socket '/run/mysqld/mysqld.sock' (2)"); 98)
[2025-05-01T15:07:27.511+0000] {local_task_job_runner.py:240} INFO - Task exited with return code 1
[2025-05-01T15:07:27.566+0000] {taskinstance.py:3503} INFO - 0 downstream tasks scheduled from follow-on schedule check
[2025-05-01T15:07:27.612+0000] {local_task_job_runner.py:222} INFO - ::endgroup::
